<?xml version="1.0" ?>
<!-- =================================================================================== -->
<!-- |    This document was autogenerated by xacro from /mnt/c/Users/maxim/OneDriveFHTW/FHTW/4_Semester/ROS/catkin_ws/src/taurob_tracker_description/urdf/taurob_tracker_flipper.xacro | -->
<!-- |    EDITING THIS FILE BY HAND IS NOT RECOMMENDED                                 | -->
<!-- =================================================================================== -->
<!--<robot name="taurob_tracker" xmlns:xacro="http://www.ros.org/wiki/xacro">-->
<robot name="taurob_tracker">
  <arg default="0.0" name="laser_rot"/>
  <!-- ros_control plugin -->
  <gazebo>
    <plugin filename="libgazebo_ros_control_select_joints.so" name="gazebo_ros_control_select_joints">
      <robotNamespace>/taurob_tracker</robotNamespace>
      <robotSimType>gazebo_ros_control/DefaultRobotHWSim</robotSimType>
      <joint>flipper_joint_front</joint>
    </plugin>
  </gazebo>
  <gazebo>
    <plugin filename="libgazebo_ros_force_based_move.so" name="force_based_move_control1">
      <commandTopic>/taurob_tracker/cmd_vel_raw</commandTopic>
      <odometryTopic>odom</odometryTopic>
      <odometryFrame>odom</odometryFrame>
      <odometryRate>20.0</odometryRate>
      <robotBaseFrame>base_link</robotBaseFrame>
      <yaw_velocity_p_gain>250</yaw_velocity_p_gain>
      <!--<x_velocity_p_gain>500</x_velocity_p_gain>-->
      <publishOdometryTf>0</publishOdometryTf>
    </plugin>
  </gazebo>
  <gazebo reference="imu_link">
    <gravity>true</gravity>
    <sensor name="imu_sensor" type="imu">
      <always_on>true</always_on>
      <update_rate>100</update_rate>
      <visualize>true</visualize>
      <topic>/taurob_tracker/imu/data</topic>
      <plugin filename="libgazebo_ros_imu_sensor.so" name="imu_plugin">
        <topicName>/taurob_tracker/imu/data</topicName>
        <bodyName>imu_link</bodyName>
        <updateRateHZ>10.0</updateRateHZ>
        <gaussianNoise>0.0</gaussianNoise>
        <xyzOffset>0 0 0</xyzOffset>
        <rpyOffset>0 0 0</rpyOffset>
        <frameName>base_link</frameName>
      </plugin>
      <pose>0 0 0 0 0 0</pose>
    </sensor>
  </gazebo>
  <gazebo>
    <plugin filename="libhector_gazebo_ros_gps.so" name="gps_controller">
      <alwayson>true</alwayson>
      <updaterate>1.0</updaterate>
      <bodyname>imu_link</bodyname>
      <robotNamespace>/taurob_tracker</robotNamespace>
      <topicname>/fix</topicname>
      <velocitytopicname>fix_velocity</velocitytopicname>
      <drift>5.0 5.0 5.0</drift>
      <gaussiannoise>0.1 0.1 0.1</gaussiannoise>
      <velocitydrift>0 0 0</velocitydrift>
      <velocitygaussiannoise>0.1 0.1 0.1</velocitygaussiannoise>
      <referenceLatitude>48.354717</referenceLatitude>
      <referenceLongitude>15.884882</referenceLongitude>
      <referenceAltitude>250</referenceAltitude>
    </plugin>
  </gazebo>
  <gazebo>
    <plugin filename="libroboticsgroup_gazebo_mimic_joint_plugin.so" name="flipper_mimic_control">
      <robotNamespace>/taurob_tracker</robotNamespace>
      <joint>flipper_joint_front</joint>
      <mimicJoint>flipper_joint_back</mimicJoint>
      <multiplier>0.0</multiplier>
    </plugin>
  </gazebo>
  <!-- Chassis link -->
  <gazebo reference="chassis_link">
    <material>Gazebo/White</material>
  </gazebo>
  <!-- Flipper front link -->
  <gazebo reference="flipper_link_front">
    <mu1>200.0</mu1>
    <mu2>100.0</mu2>
    <kp>500.0</kp>
    <kd>100.0</kd>
    <minDepth>0.001</minDepth>
    <maxVel>1.0</maxVel>
    <material>Gazebo/Black</material>
  </gazebo>
  <!-- Flipper back link -->
  <gazebo reference="flipper_link_back">
    <mu1>0.0</mu1>
    <mu2>0.0</mu2>
    <kp>1000000.0</kp>
    <kd>100.0</kd>
    <minDepth>0.001</minDepth>
    <maxVel>1.0</maxVel>
    <material>Gazebo/Black</material>
  </gazebo>
  <material name="black">
    <color rgba="0.0 0.0 0.0 1.0"/>
  </material>
  <material name="blue">
    <color rgba="0.0 0.0 0.8 1.0"/>
  </material>
  <material name="green">
    <color rgba="0.0 0.8 0.0 1.0"/>
  </material>
  <material name="grey">
    <color rgba="0.2 0.2 0.2 1.0"/>
  </material>
  <material name="orange">
    <color rgba="1.0 0.4235294117647059 0.0392156862745098 1.0"/>
  </material>
  <material name="brown">
    <color rgba="0.8705882352941177 0.8117647058823529 0.7647058823529411 1.0"/>
  </material>
  <material name="red">
    <color rgba="0.8 0.0 0.0 1.0"/>
  </material>
  <material name="white">
    <color rgba="1.0 1.0 1.0 1.0"/>
  </material>
  <link name="base_link"/>
  <joint name="chassis_joint" type="fixed">
    <origin rpy="0 0 0" xyz="0.122 0 0.193"/>
    <parent link="base_link"/>
    <child link="chassis_link"/>
  </joint>
  <!-- Chassis Link -->
  <link name="chassis_link">
    <inertial>
      <origin rpy="0 0 0" xyz="-0.25 0.0 -0.1"/>
      <mass value="30.0"/>
      <inertia ixx="0.7250000000000001" ixy="0.0" ixz="0.0" iyy="1.189" iyz="0.0" izz="1.714"/>
    </inertial>
    <!-- Body -->
    <visual>
      <origin rpy="0 0 -1.5707963267948966" xyz="0.0 0.0 0.0"/>
      <geometry>
        <mesh filename="package://taurob_tracker_description/meshes/tracker_chassis_no_tracks.dae" scale="0.01 0.01 0.01"/>
      </geometry>
      <!--<material name="white" />-->
    </visual>
    <collision>
      <origin rpy="0 0 0" xyz="-0.252 0.0 -0.075"/>
      <geometry>
        <box size="0.7 0.4075 0.2"/>
      </geometry>
    </collision>
    <!-- Fake Wheels -->
    <collision>
      <origin rpy="1.5707963267948966 0 0" xyz="0 0.24375 -0.09"/>
      <geometry>
        <cylinder length="0.0925" radius="0.13"/>
      </geometry>
    </collision>
    <collision>
      <origin rpy="1.5707963267948966 0 0" xyz="0 -0.24375 -0.09"/>
      <geometry>
        <cylinder length="0.0925" radius="0.13"/>
      </geometry>
    </collision>
    <collision>
      <origin rpy="1.5707963267948966 0 0" xyz="-0.5 0.24375 -0.09"/>
      <geometry>
        <cylinder length="0.0925" radius="0.13"/>
      </geometry>
    </collision>
    <collision>
      <origin rpy="1.5707963267948966 0 0" xyz="-0.5 -0.24375 -0.09"/>
      <geometry>
        <cylinder length="0.0925" radius="0.13"/>
      </geometry>
    </collision>
  </link>
  <!-- Flipper front link -->
  <link name="flipper_link_front">
    <inertial>
      <origin rpy="0 0 0" xyz="0.122 0.0 0.0"/>
      <mass value="2.0"/>
      <inertia ixx="0.010896796683333331" ixy="0.0" ixz="0.0" iyy="0.04685929668333333" iyz="0.0" izz="0.047370833333333334"/>
    </inertial>
    <origin rpy="0 0 0" xyz="0 0 0"/>
    <!-- Left side -->
    <collision name="flipper_left">
      <origin rpy="-1.5707963267948966 0.0 0.0" xyz="0.45 0.24375 0"/>
      <geometry>
        <cylinder length="0.0925" radius="0.13"/>
      </geometry>
    </collision>
    <visual name="flipper_left">
      <origin rpy="0 0 -1.5707963267948966" xyz="0.122 0 0.09"/>
      <geometry>
        <mesh filename="package://taurob_tracker_description/meshes/flipper_left_forward.dae" scale="0.01 0.01 0.01"/>
      </geometry>
    </visual>
    <!-- Right side -->
    <collision name="flipper_right">
      <origin rpy="-1.5707963267948966 0.0 0.0" xyz="0.45 -0.24375 0"/>
      <geometry>
        <cylinder length="0.0925" radius="0.13"/>
      </geometry>
    </collision>
    <visual name="flipper_right">
      <origin rpy="0 0 -1.5707963267948966" xyz="0.122 0 0.09"/>
      <geometry>
        <mesh filename="package://taurob_tracker_description/meshes/flipper_right_forward.dae" scale="0.01 0.01 0.01"/>
      </geometry>
    </visual>
  </link>
  <!-- Flipper front joint -->
  <joint name="flipper_joint_front" type="revolute">
    <origin rpy="0 0 0" xyz="-0.122 0 -0.09"/>
    <axis xyz="0 -1 0"/>
    <limit effort="10000" lower="-0.8726646259971648" upper="0.5235987755982988" velocity="0.5235987755982988"/>
    <parent link="chassis_link"/>
    <child link="flipper_link_front"/>
  </joint>
  <!-- Flipper back -->
  <link name="flipper_link_back">
    <inertial>
      <origin rpy="0 0 0" xyz="0.0 0.0 0.0"/>
      <mass value="2.0"/>
      <inertia ixx="0.010896796683333331" ixy="0.0" ixz="0.0" iyy="0.015609296683333333" iyz="0.0" izz="0.016120833333333334"/>
    </inertial>
    <origin rpy="0 0 0" xyz="0 0 0"/>
    <!-- Wheel back -->
    <visual>
      <origin rpy="0 0 -1.5707963267948966" xyz="0.502 0 0.09"/>
      <geometry>
        <mesh filename="package://taurob_tracker_description/meshes/flipper_left_back.dae" scale="0.01 0.01 0.01"/>
      </geometry>
    </visual>
    <visual name="flipper_right">
      <origin rpy="0 0 -1.5707963267948966" xyz="0.502 0 0.09"/>
      <geometry>
        <mesh filename="package://taurob_tracker_description/meshes/flipper_right_back.dae" scale="0.01 0.01 0.01"/>
      </geometry>
    </visual>
  </link>
  <joint name="flipper_joint_back" type="revolute">
    <origin rpy="0 0 0" xyz="-0.492 0 -0.09"/>
    <axis xyz="0 -1 0"/>
    <mimic joint="flipper_joint_front" multiplier="0.5"/>
    <limit effort="10000" lower="-2.9670597283903604" upper="3.141592653589793" velocity="62.83185307179586"/>
    <parent link="chassis_link"/>
    <child link="flipper_link_back"/>
  </joint>
  <joint name="velodyne_base_mount_joint" type="fixed">
    <origin rpy="0 0 1.5707963267948966" xyz="-0.66375 0 0.898"/>
    <parent link="chassis_link"/>
    <child link="velodyne_base_link"/>
  </joint>
  <link name="velodyne_base_link">
    <inertial>
      <mass value="0.83"/>
      <origin xyz="0 0 0.03585"/>
      <inertia ixx="0.000908059425" ixy="0" ixz="0" iyy="0.000908059425" iyz="0" izz="0.0011049624"/>
    </inertial>
    <visual>
      <geometry>
        <mesh filename="package://velodyne_description/meshes/VLP16_base_1.dae"/>
      </geometry>
    </visual>
    <visual>
      <geometry>
        <mesh filename="package://velodyne_description/meshes/VLP16_base_2.dae"/>
      </geometry>
    </visual>
    <collision>
      <origin rpy="0 0 0" xyz="0 0 0.03585"/>
      <geometry>
        <cylinder length="0.0717" radius="0.0516"/>
      </geometry>
    </collision>
  </link>
  <joint name="velodyne_base_scan_joint" type="fixed">
    <origin rpy="0 0 0" xyz="0 0 0.0377"/>
    <parent link="velodyne_base_link"/>
    <child link="velodyne"/>
  </joint>
  <link name="velodyne">
    <inertial>
      <mass value="0.01"/>
      <origin xyz="0 0 0"/>
      <inertia ixx="1e-7" ixy="0" ixz="0" iyy="1e-7" iyz="0" izz="1e-7"/>
    </inertial>
    <visual>
      <origin xyz="0 0 -0.0377"/>
      <geometry>
        <mesh filename="package://velodyne_description/meshes/VLP16_scan.dae"/>
      </geometry>
    </visual>
  </link>
  <!-- Gazebo requires the velodyne_gazebo_plugins package -->
  <gazebo reference="velodyne">
    <sensor name="velodyne-VLP16" type="gpu_ray">
      <pose>0 0 0 0 0 0</pose>
      <visualize>false</visualize>
      <update_rate>10</update_rate>
      <ray>
        <scan>
          <horizontal>
            <samples>440</samples>
            <resolution>1</resolution>
            <min_angle>-3.141592653589793</min_angle>
            <max_angle>3.141592653589793</max_angle>
          </horizontal>
          <vertical>
            <samples>16</samples>
            <resolution>1</resolution>
            <min_angle>-0.2617993877991494</min_angle>
            <max_angle> 0.2617993877991494</max_angle>
          </vertical>
        </scan>
        <range>
          <min>0.3</min>
          <max>31.0</max>
          <resolution>0.001</resolution>
        </range>
        <noise>
          <type>gaussian</type>
          <mean>0.0</mean>
          <stddev>0.0</stddev>
        </noise>
      </ray>
      <plugin filename="libgazebo_ros_velodyne_gpu_laser.so" name="gazebo_ros_laser_controller">
        <topicName>/velodyne_points</topicName>
        <frameName>velodyne</frameName>
        <min_range>0.9</min_range>
        <max_range>30.0</max_range>
        <gaussianNoise>0.008</gaussianNoise>
      </plugin>
    </sensor>
  </gazebo>
  <!-- IMU -->
  <link name="imu_link"/>
  <joint name="imu_joint" type="fixed">
    <origin rpy="0 0 0" xyz="0 0 -0.09"/>
    <parent link="chassis_link"/>
    <child link="imu_link"/>
  </joint>
  <!-- Transmissions -->
  <transmission name="trans_flipper_front">
    <type>transmission_interface/SimpleTransmission</type>
    <joint name="flipper_joint_front">
      <!--<hardwareInterface>hardware_interface/EffortJointInterface</hardwareInterface>-->
      <hardwareInterface>hardware_interface/PositionJointInterface</hardwareInterface>
    </joint>
    <actuator name="flipper_motor_front">
      <hardwareInterface>hardware_interface/EffortJointInterface</hardwareInterface>
      <mechanicalReduction>1</mechanicalReduction>
    </actuator>
  </transmission>
  <transmission name="trans_flipper_back">
    <type>transmission_interface/SimpleTransmission</type>
    <joint name="flipper_joint_back">
      <!--<hardwareInterface>hardware_interface/EffortJointInterface</hardwareInterface>-->
      <hardwareInterface>hardware_interface/PositionJointInterface</hardwareInterface>
    </joint>
    <actuator name="flipper_motor_back">
      <hardwareInterface>hardware_interface/EffortJointInterface</hardwareInterface>
      <mechanicalReduction>1</mechanicalReduction>
    </actuator>
  </transmission>
</robot>

